Workbook
Name AsOf: Control!$B$6
Name StartLong: Control!$B$7
Name StartWar: Control!$B$8
Name StartCredit: Control!$B$9
Name StartYTD: Control!$B$10
Name Start5Y: Control!$B$11
Name Start10Y: Control!$B$12
Name CorrWindow: Control!$B$13
Name VolWindow: Control!$B$14

Sheet Readme
A1: JPY bull steepener — the working book
A2: Built off-terminal, run on-terminal. Every figure is a live BDH / BDP / BQL formula, so #NAME? until the Bloomberg add-in loads is the file working as intended.
A5: What is here, and what each tab is for
A6: Control | B6: Dates and windows. Every formula in the book points here; change the as-of date once and the whole file moves.
A7: BullSteepener | B7: The trade. Live indications, the mean-reversion tests, entry and exit levels derived from those tests, a 26-week forward backtest of the entry rule, instrument choice with a live hedge ratio and carry, and the decomposition that answers the steepest-since-2010 objection. Four charts.
A8: JPYEvidence | B8: The macro evidence, charted. Headline against core-core CPI with the 2% target, and real wages against household spending. Two charts.
A9: BOJPath | B9: What is priced against what is printing — OIS 1y and 2y, the 1y1y forward, core-core CPI, and the Shunto settlement. Two charts.
A10: CurveSlope | B10: Six curve slopes against their own five-year range, with an explainer written for the room and a punchline cell that rewrites itself from the refreshed numbers. Three charts.
A11: RealYield | B11: Ten-year real yields across five Asian markets. Feeds the MacroLink real-yield chart, which adds Japan's two-year — the point being that the negative real yield is at the front end.
A12: Payoff | B12: What it makes by state of the world, an expected value for both expressions, sizing against the rates sleeve, and a falsification calendar with a date and a number on every line. Two charts.
A13: MacroLink | B13: The artefacts that tie the trade to the macro framing: channel-to-instrument map, scenario strip, positioning table, and three charts. Three charts, three tables.
A15: How to run it
B16: 1. Open on the Bloomberg laptop and confirm the ribbon is present.
B17: 2. Control tab — set the as-of date, or leave =TODAY() for a live book.
B18: 3. Bloomberg > Refresh > Refresh Entire Workbook.
B19: 4. Check the date alignment cell near the top of each tab reads 0 / OK before trusting a number.
B20: 5. The charts redraw themselves — they point at the ranges the formulas spill into, not at pasted values.
A22: This file is a build artefact. It is generated by data-puller/build_data_puller.py alongside the full Q2 book and shares every sheet builder with it, so the two cannot disagree. Never repair it by hand — fix the script and rebuild, or the fix is lost the next time anyone regenerates it.

Sheet Control
A1: Control panel
A2: Every formula in this workbook points here. Change a date once and the whole book — and every chart — moves with it.
A5: Parameter | B5: Value | C5: What it drives
A6: As-of date | B6: =TODAY() | C6: End date for every BDH pull. Set to a fixed date to freeze the book for the presentation.
A7: Long history start | B7: =DATE(YEAR(AsOf)-3,1,1) | C7: Main window: ERP history, stock-bond correlation. Three years keeps the file light; see ROWS_DAILY in the build script before extending it.
A8: War window start | B8: =DATE(2026,2,25) | C8: Pre-Iran-war baseline for the 3.97% to 4.71% 10y chart.
A9: Credit history start | B9: =DATE(1996,1,1) | C9: Full HY OAS history, so the percentile is computed not quoted.
A10: YTD start | B10: =DATE(YEAR(AsOf),1,1) | C10: Year-to-date window for the breadth chart. Follows the as-of date automatically.
A11: 5y start (monthly) | B11: =DATE(YEAR(AsOf)-5,MONTH(AsOf),1) | C11: Valuation bands and curve-slope ranges on the Asia tabs. Monthly, so five years is 60 points.
A12: 10y start (monthly) | B12: =DATE(YEAR(AsOf)-10,MONTH(AsOf),1) | C12: ERP percentile history. Monthly, 120 points; raise ROWS_MONTHLY in the build script before extending.
A13: Correlation window | B13: 60 | C13: Trading days in the rolling stock-bond correlation.
A14: Vol window | B14: 30 | C14: Trading days for realised vol comparisons.
A17: Common BDH option strings
A18: Name | B18: String | C18: Effect
A19: Daily, ascending, filled | B19: "Dir=V","Sort=A","Fill=P","Days=A" | C19: Vertical layout, oldest first, previous value carried over non-trading days.
A20: Weekly | B20: "Dir=V","Sort=A","Per=W","Fill=P" | C20: Weekly periodicity — use for the long credit series if the daily pull is slow.
A21: Monthly | B21: "Dir=V","Sort=A","Per=M" | C21: Monthly — CPI and other macro releases.
A24: Before the presentation: set As-of date to a hard date (=DATE(2026,7,31) or the morning of), hit Bloomberg > Refresh Worksheets, then check the verification list on the Notes tab.

Sheet Flow
A1: The running order
A2: Eight steps. Each one proves a single thing and hands to the next. If a step cannot be stated in one sentence it is not ready.
A5: The one-sentence version, before anything else
B6: The market prices two more BoJ hikes, the Bank guides hawkish, and positioning is hawkish — so the one outcome nobody is paid for is the one the Bank's own terms-of-trade analysis points to, and that is what we are buying, with defined premium.
A9: # | B9: Step | C9: Tab / chart | D9: What it proves | E9: The handoff into the next step
A10: 1 | B10: Where the curve is, and the objection | C10: CurveSlope · range marker | D10: JGB 2s10s sits near the top of its five-year range. Put the objection up yourself before anyone raises it. | E10: "That is the level. Now look at how it got there."
A11: 2 | B11: How it got there | C11: BullSteepener · decomposition | D11: Every window is bear steepening: both legs sold off and the long end sold off more. The 2-year has never rallied in this cycle. | E11: "So the steepening is entirely a long-end story. What about the front end?"
A12: 3 | B12: What the front end holds | C12: BullSteepener · live indications | D12: The 2-year sits roughly 55bp above the policy rate — about two priced hikes. In 2010, at a comparable curve, it sat at the policy rate with nothing to give back. | E12: "That inventory is the asset. The question is what could release it."
A13: 4 | B13: The one thing that could release it | C13: JPYEvidence · CPI, wages vs spending | D13: Core-core at 1.7%, the lowest since August 2022. Household spending down seven months. Income rising and not being spent. | E13: "The wage channel is working on paper and not in prices."
A14: 5 | B14: Be honest about the other side | C14: Payoff · falsification calendar | D14: Ueda guides CPI clearly above 2% in H2, flags upside risk to underlying CPI, and says the Bank could go faster. Q2 GDP revised up. Two members want to accelerate. | E14: "So I am not forecasting a pause. Here is what I am actually doing."
A15: 6 | B15: Reframe: asymmetry, not forecast | C15: MacroLink · positioning | D15: Consensus is JGB 10s30s flatteners and US steepeners. Nobody is in JPY 2s10s. Price, guidance and positioning all point one way, which is what makes the other side cheap. | E15: "Cheap relative to what? Here is the payoff."
A16: 7 | B16: What it makes, and what it costs | C16: Payoff · payoff by state | D16: The conditional loses premium in four of five states and pays in the one that matters. The cash spread loses real money in two. | E16: "Which is why the instrument is not the obvious one."
A17: 8 | B17: The instrument, and why the tests chose it | C17: BullSteepener · tests | D17: Mean reversion fails at +1.7SD, the long end has an issuance cut behind it, and guidance is against us. Three independent reasons not to own the cash spread and to buy defined premium instead. | E17: Close on the calendar: 18 Sep, 29 Oct, and the core-core print that ends it.
A20: If you only get three minutes
B21: 1. | D21: Steps 1–3. The curve is steep, all of it came from the long end, and the 2-year has never rallied.
B22: 2. | D22: Step 5. Volunteer the hawkish guidance. It buys you every remaining minute of credibility.
B23: 3. | D23: Steps 6–8. Nobody is positioned for the alternative, so the alternative is cheap, so buy it with defined premium.
A25: The four questions you will get, and the answers
B26: "You are pitching a steepener at the steepest curve since 2010." | D26: Correct, and every basis point of it came from the long end. The 2-year has never rallied. In 2010 it sat at the policy rate with nothing to give back; today it holds about two hikes. I am buying the leg that has not moved.
B27: "The BoJ has told you it is hiking. You are fighting the central bank." | D27: Yes, and that is why the position is defined-premium rather than a cash spread. I am not forecasting a pause — I am buying an outcome that price, guidance and positioning have all agreed is not going to happen. That agreement is what makes it cheap.
B28: "Your own statistics say do not do this." | D28: They say do not own the cash spread, and I do not. The z-score is +1.7, the Dickey-Fuller test cannot reject a unit root, and the variance ratio says trending. Three tests, one conclusion, and it changed the instrument rather than the view. Five years of history also contains no example of a BoJ that pauses, which is why I am not leaning on a backtest.
B29: "What ends the trade?" | D29: Two consecutive core-core prints above 2.2% and rising, an upward revision to the FY27 CPI forecast on 29 October, or USD/JPY through 165 and holding. All three are dated and none of them requires my judgement.
A32: One discipline worth keeping. This tab was rewritten once already, when the July guidance came in and made the earlier framing — that the Bank's own forecasts did not support the priced hikes — no longer true. The trade survived because the argument changed shape rather than being defended. If the next print does the same thing, rewrite it again rather than adding a caveat.

Sheet RealYield
A1: 10-year real yields — nominal less core CPI
A2: Slide 2, exhibit 1. The cleanest single measure of whether a bond market pays you to own it. Ex-post real, not breakeven-implied — Asia has no liquid linker market to imply it from.
A5: Market | B5: 10y ticker | C5: Nominal, % | D5: Core CPI ticker | E5: Core CPI y/y, % | F5: Real yield, %
A6: China (CGB) | B6: GTCNY10Y Govt | C6: =BDP($B6,"PX_LAST") | D6: CNCPICYY Index | E6: =BDP($D6,"PX_LAST") | F6: =IFERROR(C6-E6,"")
A7: Hong Kong (HKGB) | B7: GTHKD10Y Govt | C7: =BDP($B7,"PX_LAST") | D7: HKCPIY Index | E7: =BDP($D7,"PX_LAST") | F7: =IFERROR(C7-E7,"")
A8: Korea (KTB) | B8: GTKRW10Y Govt | C8: =BDP($B8,"PX_LAST") | D8: KOCPIXFY Index | E8: =BDP($D8,"PX_LAST") | F8: =IFERROR(C8-E8,"")
A9: Japan (JGB) | B9: GTJPY10Y Govt | C9: =BDP($B9,"PX_LAST") | D9: JCPNEFEY Index | E9: =BDP($D9,"PX_LAST") | F9: =IFERROR(C9-E9,"")
A10: Taiwan (TWGB) | B10: GTTWD10Y Govt | C10: =BDP($B10,"PX_LAST") | D10: TWCPCYOY Index | E10: =BDP($D10,"PX_LAST") | F10: =IFERROR(C10-E10,"")
A13: Core rather than headline, deliberately. Headline across this region is currently an energy number — the memo's whole Channel 2 argument — so a headline-deflated real yield would be measuring the oil price rather than the bond market. Say this if asked; it is the obvious challenge to the exhibit.
A17: Every ticker on this tab is unconfirmed. The GT convention was given for Japan only; CNY, HKD, KRW and TWD follow the same pattern. The five core CPI identifiers were declined outright by the help desk. Hong Kong is the least safe of them — the composite CPI and the underlying (core) CPI are separate series there, and it is the underlying one this needs.
A21: One frequency mismatch worth stating on the slide: the yields are live and the CPI prints are monthly and lagged. The real yield is therefore as of the last CPI print, not as of this morning. That is the standard construction, but volunteer it rather than being asked.

Sheet BOJPath
A1: The BoJ path against what actually drives it
A2: Slide 2, exhibit 2. OIS tells you what is priced; core-core CPI and the Shunto settlement tell you what the BoJ is looking at. The exhibit is the gap between them.
A5: Measure | B5: Ticker | C5: Value, % | D5: Note
A6: BoJ policy rate | B6: BOJDTR Index | C6: =BDP($B6,"PX_LAST") | D6: 1.00% at the June meeting, highest since Sep-1995.
A7: JPY OIS, 1y | B7: JYSO1 Curncy | C7: =BDP($B7,"PX_LAST") | D7: What is priced over the next year.
A8: JPY OIS, 2y | B8: JYSO2 Curncy | C8: =BDP($B8,"PX_LAST") | D8: Two-year point.
A9: Implied 1y1y forward | C9: =IFERROR(2*C8-C7,"") | D9: Linear approximation, 2 x 2y less 1y. Good enough at these tenors and it shows its own working; use FWCM <GO> if you want the exact forward.
A10: Priced hikes to 1y, count | C10: =IFERROR((C7-C6)/0.25,"") | D10: 25bp increments. This is the number to say out loud.
A11: Japan core-core CPI y/y | B11: JCPNEFEY Index | C11: =BDP($B10,"PX_LAST") | D11: Ex fresh food AND energy — the series the BoJ targets in practice.
A12: Japan core CPI y/y | B12: JNCPIXFY Index | C12: =BDP($B11,"PX_LAST") | D12: Ex fresh food only. Carried for contrast, not for the chart.
A14: Shunto — the one input on this tab that may not pull
A15: Year | B15: Candidate ticker | C15: Pulled | D15: Manual entry | E15: Used | F15: Rengo publishes the annual settlement each spring. If the ticker resolves, the Used column takes it; if not, type the published figure into Manual entry and the chart still draws. This is the only place in the workbook where a typed number is permitted, and it is permitted because the alternative is a missing series rather than a wrong one — the Used column shows which source it took.
A16: =YEAR(AsOf)-5 | B16: JNSHUNTO Index | C16: =IFERROR(BDH($B16,"PX_LAST",DATE(A16,4,1),DATE(A16,7,31),"Dir=H","Sort=D","cols=1;rows=1"),"") | E16: =IF(C16<>"",C16,D16)
A17: =YEAR(AsOf)-4 | B17: JNSHUNTO Index | C17: =IFERROR(BDH($B17,"PX_LAST",DATE(A17,4,1),DATE(A17,7,31),"Dir=H","Sort=D","cols=1;rows=1"),"") | E17: =IF(C17<>"",C17,D17)
A18: =YEAR(AsOf)-3 | B18: JNSHUNTO Index | C18: =IFERROR(BDH($B18,"PX_LAST",DATE(A18,4,1),DATE(A18,7,31),"Dir=H","Sort=D","cols=1;rows=1"),"") | E18: =IF(C18<>"",C18,D18)
A19: =YEAR(AsOf)-2 | B19: JNSHUNTO Index | C19: =IFERROR(BDH($B19,"PX_LAST",DATE(A19,4,1),DATE(A19,7,31),"Dir=H","Sort=D","cols=1;rows=1"),"") | E19: =IF(C19<>"",C19,D19)
A20: =YEAR(AsOf)-1 | B20: JNSHUNTO Index | C20: =IFERROR(BDH($B20,"PX_LAST",DATE(A20,4,1),DATE(A20,7,31),"Dir=H","Sort=D","cols=1;rows=1"),"") | E20: =IF(C20<>"",C20,D20)
A21: =YEAR(AsOf)-0 | B21: JNSHUNTO Index | C21: =IFERROR(BDH($B21,"PX_LAST",DATE(A21,4,1),DATE(A21,7,31),"Dir=H","Sort=D","cols=1;rows=1"),"") | E21: =IF(C21<>"",C21,D21)
A24: Monthly history — what is priced against what is printing | R24: Staging — one BQL call per security. Each spills DATE and value; the working columns on the left look them up by date. Blocks: R = JPY OIS 1y · V = JPY OIS 2y · Z = Japan core-core CPI. If a block comes back with an extra ID column, shift that block's value column by one — nothing else needs to change.
A25: All three series are in per cent, so they share one axis. A secondary axis here would be a way of making two unrelated scales look like they move together, which is exactly the thing to avoid on this chart.
A26: Date alignment check | C26: =IFERROR(SUMPRODUCT(--($R$28:$R$158<>"")*($V$28:$V$158<>"")*($R$28:$R$158<>$V$28:$V$158))+SUMPRODUCT(--($R$28:$R$158<>"")*($Z$28:$Z$158<>"")*($R$28:$R$158<>$Z$28:$Z$158)),"") | D26: =IF(C26="","",IF(C26=0,"OK — blocks are row-aligned","MISALIGNED: "&C26&" rows differ. Do not use these numbers; switch the value columns to INDEX/MATCH on the date.")) | R26: =BQL("JYSO1 Curncy","px_last(frq=M, dates=range("&TEXT(Start5Y,"yyyy-mm-dd")&","&TEXT(AsOf,"yyyy-mm-dd")&"), fill=prev)") | V26: =BQL("JYSO2 Curncy","px_last(frq=M, dates=range("&TEXT(Start5Y,"yyyy-mm-dd")&","&TEXT(AsOf,"yyyy-mm-dd")&"), fill=prev)") | Z26: =BQL("JCPNEFEY Index","px_last(frq=M, dates=range("&TEXT(Start5Y,"yyyy-mm-dd")&","&TEXT(AsOf,"yyyy-mm-dd")&"), fill=prev)")
A27: Date | B27: JPY OIS 1y, % | C27: JPY OIS 2y, % | D27: Core-core CPI y/y, % | E27: 1y1y forward, % | F27: Shunto, %
A28: =IFERROR(INDEX($R$28:$R$158,ROW()-27),"") | B28: =IFERROR(INDEX($S$28:$S$158,ROW()-27),"") | C28: =IFERROR(INDEX($W$28:$W$158,ROW()-27),"") | D28: =IFERROR(INDEX($AA$28:$AA$158,ROW()-27),"") | E28: =IFERROR(2*C28-B28,"") | F28: =IFERROR(INDEX($E$16:$E$21,MATCH(YEAR(A28),$A$16:$A$21,0)),"")
A29: =IFERROR(INDEX($R$28:$R$158,ROW()-27),"") | B29: =IFERROR(INDEX($S$28:$S$158,ROW()-27),"") | C29: =IFERROR(INDEX($W$28:$W$158,ROW()-27),"") | D29: =IFERROR(INDEX($AA$28:$AA$158,ROW()-27),"") | E29: =IFERROR(2*C29-B29,"") | F29: =IFERROR(INDEX($E$16:$E$21,MATCH(YEAR(A29),$A$16:$A$21,0)),"")
A30: =IFERROR(INDEX($R$28:$R$158,ROW()-27),"") | B30: =IFERROR(INDEX($S$28:$S$158,ROW()-27),"") | C30: =IFERROR(INDEX($W$28:$W$158,ROW()-27),"") | D30: =IFERROR(INDEX($AA$28:$AA$158,ROW()-27),"") | E30: =IFERROR(2*C30-B30,"") | F30: =IFERROR(INDEX($E$16:$E$21,MATCH(YEAR(A30),$A$16:$A$21,0)),"")
A31: =IFERROR(INDEX($R$28:$R$158,ROW()-27),"") | B31: =IFERROR(INDEX($S$28:$S$158,ROW()-27),"") | C31: =IFERROR(INDEX($W$28:$W$158,ROW()-27),"") | D31: =IFERROR(INDEX($AA$28:$AA$158,ROW()-27),"") | E31: =IFERROR(2*C31-B31,"") | F31: =IFERROR(INDEX($E$16:$E$21,MATCH(YEAR(A31),$A$16:$A$21,0)),"")
A32: =IFERROR(INDEX($R$28:$R$158,ROW()-27),"") | B32: =IFERROR(INDEX($S$28:$S$158,ROW()-27),"") | C32: =IFERROR(INDEX($W$28:$W$158,ROW()-27),"") | D32: =IFERROR(INDEX($AA$28:$AA$158,ROW()-27),"") | E32: =IFERROR(2*C32-B32,"") | F32: =IFERROR(INDEX($E$16:$E$21,MATCH(YEAR(A32),$A$16:$A$21,0)),"")
A33: =IFERROR(INDEX($R$28:$R$158,ROW()-27),"") | B33: =IFERROR(INDEX($S$28:$S$158,ROW()-27),"") | C33: =IFERROR(INDEX($W$28:$W$158,ROW()-27),"") | D33: =IFERROR(INDEX($AA$28:$AA$158,ROW()-27),"") | E33: =IFERROR(2*C33-B33,"") | F33: =IFERROR(INDEX($E$16:$E$21,MATCH(YEAR(A33),$A$16:$A$21,0)),"")
A34: =IFERROR(INDEX($R$28:$R$158,ROW()-27),"") | B34: =IFERROR(INDEX($S$28:$S$158,ROW()-27),"") | C34: =IFERROR(INDEX($W$28:$W$158,ROW()-27),"") | D34: =IFERROR(INDEX($AA$28:$AA$158,ROW()-27),"") | E34: =IFERROR(2*C34-B34,"") | F34: =IFERROR(INDEX($E$16:$E$21,MATCH(YEAR(A34),$A$16:$A$21,0)),"")
A35: =IFERROR(INDEX($R$28:$R$158,ROW()-27),"") | B35: =IFERROR(INDEX($S$28:$S$158,ROW()-27),"") | C35: =IFERROR(INDEX($W$28:$W$158,ROW()-27),"") | D35: =IFERROR(INDEX($AA$28:$AA$158,ROW()-27),"") | E35: =IFERROR(2*C35-B35,"") | F35: =IFERROR(INDEX($E$16:$E$21,MATCH(YEAR(A35),$A$16:$A$21,0)),"")
A36: =IFERROR(INDEX($R$28:$R$158,ROW()-27),"") | B36: =IFERROR(INDEX($S$28:$S$158,ROW()-27),"") | C36: =IFERROR(INDEX($W$28:$W$158,ROW()-27),"") | D36: =IFERROR(INDEX($AA$28:$AA$158,ROW()-27),"") | E36: =IFERROR(2*C36-B36,"") | F36: =IFERROR(INDEX($E$16:$E$21,MATCH(YEAR(A36),$A$16:$A$21,0)),"")
A37: =IFERROR(INDEX($R$28:$R$158,ROW()-27),"") | B37: =IFERROR(INDEX($S$28:$S$158,ROW()-27),"") | C37: =IFERROR(INDEX($W$28:$W$158,ROW()-27),"") | D37: =IFERROR(INDEX($AA$28:$AA$158,ROW()-27),"") | E37: =IFERROR(2*C37-B37,"") | F37: =IFERROR(INDEX($E$16:$E$21,MATCH(YEAR(A37),$A$16:$A$21,0)),"")
A38: =IFERROR(INDEX($R$28:$R$158,ROW()-27),"") | B38: =IFERROR(INDEX($S$28:$S$158,ROW()-27),"") | C38: =IFERROR(INDEX($W$28:$W$158,ROW()-27),"") | D38: =IFERROR(INDEX($AA$28:$AA$158,ROW()-27),"") | E38: =IFERROR(2*C38-B38,"") | F38: =IFERROR(INDEX($E$16:$E$21,MATCH(YEAR(A38),$A$16:$A$21,0)),"")
A39: =IFERROR(INDEX($R$28:$R$158,ROW()-27),"") | B39: =IFERROR(INDEX($S$28:$S$158,ROW()-27),"") | C39: =IFERROR(INDEX($W$28:$W$158,ROW()-27),"") | D39: =IFERROR(INDEX($AA$28:$AA$158,ROW()-27),"") | E39: =IFERROR(2*C39-B39,"") | F39: =IFERROR(INDEX($E$16:$E$21,MATCH(YEAR(A39),$A$16:$A$21,0)),"")
... A157: =IFERROR(INDEX($R$28:$R$158,ROW()-27),"") | B157: =IFERROR(INDEX($S$28:$S$158,ROW()-27),"") | C157: =IFERROR(INDEX($W$28:$W$158,ROW()-27),"") | D157: =IFERROR(INDEX($AA$28:$AA$158,ROW()-27),"") | E157: =IFERROR(2*C157-B157,"") | F157: =IFERROR(INDEX($E$16:$E$21,MATCH(YEAR(A157),$A$16:$A$21,0)),"")
A160: JYSO1 / JYSO2 are the standard JPY OIS convention but were not confirmed. If they do not resolve, the alternatives are the OIS curve off ICVS <GO> or the TONA swap tickers. JCPNEFEY is the core-core series and is on the register as VERIFY along with every other CPI identifier.

Sheet CurveSlope
A1: Curve slopes against their own 5-year range
A2: Slide 2, exhibit 3. A slope in isolation means nothing. Against five years of its own history it tells you whether the steepener is already in the price.
A5: What this measures, in one pass
A6: The slope | B6: The long yield minus the short yield, in basis points. JGB 2s10s = the 10-year JGB yield less the 2-year. Positive means the curve is upward-sloping: you are paid more to lend for longer.
A7: Why the range | B7: A slope of +148bp tells you nothing on its own. Wide or narrow compared with what? The grey band is the highest and lowest that same slope has been over the last five years, so the question becomes: given where this curve has traded, is today steep or flat?
A8: The percentile | B8: Where today sits inside that band, 0% at the flattest five years and 100% at the steepest. Above 80% the steepening has already happened. Below 20% it has not.
A9: Where the trade is | B9: You want to PAY for steepening where the percentile is low and the story is still ahead of you, and you want to be taking the other side — or just collecting carry — where the percentile is high and the consensus trade is already on.
A10: The hook | B10: The curve everybody is talking about is usually the one already in the price. This chart finds the one nobody is talking about that is sitting at the bottom of its own five-year range.
A12: The line to say when the chart goes up
A13: =IF(COUNT(D18:D23)=0,"Refresh first — this sentence writes itself from the numbers.","The widest gap on this chart is "&INDEX(A18:A23,MATCH(MAX(H18:H23),H18:H23,0))&" at the "&TEXT(MAX(H18:H23),"0%")&" of its five-year range, against "&INDEX(A18:A23,MATCH(MIN(H18:H23),H18:H23,0))&" at the "&TEXT(MIN(H18:H23),"0%")&". One of those trades is already on. The other one is the opportunity.")
A15: A13 builds the punchline from the refreshed numbers rather than letting anyone type one. If the sentence it produces is not the argument you want to make, the argument is wrong, not the sentence.
A17: Curve | B17: Long leg | C17: Short leg | D17: Slope now, bp | E17: 5y min | F17: 5y max | G17: 5y mean | H17: Percentile | I17: Read
A18: JGB 2s10s | B18: GTJPY10Y Govt | C18: GTJPY2Y Govt | D18: =IFERROR((BDP($B18,"PX_LAST")-BDP($C18,"PX_LAST"))*100,"") | E18: =IFERROR(MIN(B$40:B$169),"") | F18: =IFERROR(MAX(B$40:B$169),"") | G18: =IFERROR(AVERAGE(B$40:B$169),"") | H18: =IFERROR(PERCENTRANK.INC(B$40:B$169,D18),"") | I18: =IF(H18="","",IF(H18>0.8,"Steep vs history — already priced",IF(H18<0.2,"Flat vs history — room to steepen","Mid-range"))) | J18: =IFERROR(F18-G18,"") | K18: =IFERROR(G18-E18,"")
A19: JGB 10s30s | B19: GTJPY30Y Govt | C19: GTJPY10Y Govt | D19: =IFERROR((BDP($B19,"PX_LAST")-BDP($C19,"PX_LAST"))*100,"") | E19: =IFERROR(MIN(C$40:C$169),"") | F19: =IFERROR(MAX(C$40:C$169),"") | G19: =IFERROR(AVERAGE(C$40:C$169),"") | H19: =IFERROR(PERCENTRANK.INC(C$40:C$169,D19),"") | I19: =IF(H19="","",IF(H19>0.8,"Steep vs history — already priced",IF(H19<0.2,"Flat vs history — room to steepen","Mid-range"))) | J19: =IFERROR(F19-G19,"") | K19: =IFERROR(G19-E19,"")
A20: UST 2s10s | B20: USGG10YR Index | C20: USGG2YR Index | D20: =IFERROR((BDP($B20,"PX_LAST")-BDP($C20,"PX_LAST"))*100,"") | E20: =IFERROR(MIN(D$40:D$169),"") | F20: =IFERROR(MAX(D$40:D$169),"") | G20: =IFERROR(AVERAGE(D$40:D$169),"") | H20: =IFERROR(PERCENTRANK.INC(D$40:D$169,D20),"") | I20: =IF(H20="","",IF(H20>0.8,"Steep vs history — already priced",IF(H20<0.2,"Flat vs history — room to steepen","Mid-range"))) | J20: =IFERROR(F20-G20,"") | K20: =IFERROR(G20-E20,"")
A21: UST 5s30s | B21: USGG30YR Index | C21: USGG5YR Index | D21: =IFERROR((BDP($B21,"PX_LAST")-BDP($C21,"PX_LAST"))*100,"") | E21: =IFERROR(MIN(E$40:E$169),"") | F21: =IFERROR(MAX(E$40:E$169),"") | G21: =IFERROR(AVERAGE(E$40:E$169),"") | H21: =IFERROR(PERCENTRANK.INC(E$40:E$169,D21),"") | I21: =IF(H21="","",IF(H21>0.8,"Steep vs history — already priced",IF(H21<0.2,"Flat vs history — room to steepen","Mid-range"))) | J21: =IFERROR(F21-G21,"") | K21: =IFERROR(G21-E21,"")
A22: Bund 2s10s | B22: GTDEM10Y Govt | C22: GTDEM2Y Govt | D22: =IFERROR((BDP($B22,"PX_LAST")-BDP($C22,"PX_LAST"))*100,"") | E22: =IFERROR(MIN(F$40:F$169),"") | F22: =IFERROR(MAX(F$40:F$169),"") | G22: =IFERROR(AVERAGE(F$40:F$169),"") | H22: =IFERROR(PERCENTRANK.INC(F$40:F$169,D22),"") | I22: =IF(H22="","",IF(H22>0.8,"Steep vs history — already priced",IF(H22<0.2,"Flat vs history — room to steepen","Mid-range"))) | J22: =IFERROR(F22-G22,"") | K22: =IFERROR(G22-E22,"")
A23: KTB 3s10s | B23: GTKRW10Y Govt | C23: GTKRW3Y Govt | D23: =IFERROR((BDP($B23,"PX_LAST")-BDP($C23,"PX_LAST"))*100,"") | E23: =IFERROR(MIN(G$40:G$169),"") | F23: =IFERROR(MAX(G$40:G$169),"") | G23: =IFERROR(AVERAGE(G$40:G$169),"") | H23: =IFERROR(PERCENTRANK.INC(G$40:G$169,D23),"") | I23: =IF(H23="","",IF(H23>0.8,"Steep vs history — already priced",IF(H23<0.2,"Flat vs history — room to steepen","Mid-range"))) | J23: =IFERROR(F23-G23,"") | K23: =IFERROR(G23-E23,"")
A25: Trade 2 is a US 5s30s steepener, and this tab is where it gets checked. If UST 2s10s is already in the top quintile of its five-year range the entry is late, and the honest answer in the room is that the trade is a carry position rather than a directional one. The exhibit is drawn to make that visible rather than to hide it.
A28: Slopes are computed from two live yields rather than pulled as a spread ticker, so the legs are visible and a wrong tenor shows up immediately. The cost is ten BDP calls instead of five, which is nothing against the daily limit.
A31: Bund 2s10s is on the chart as the control. Four of these five curves are being driven by the same thing — the long end of the US curve — and a comparator outside the region is what shows whether a slope is telling you something local or just repeating the UST move.
A34: Date alignment check | C34: =IFERROR(SUMPRODUCT(--($R$40:$R$170<>"")*($V$40:$V$170<>"")*($R$40:$R$170<>$V$40:$V$170))+SUMPRODUCT(--($R$40:$R$170<>"")*($Z$40:$Z$170<>"")*($R$40:$R$170<>$Z$40:$Z$170))+SUMPRODUCT(--($R$40:$R$170<>"")*($AD$40:$AD$170<>"")*($R$40:$R$170<>$AD$40:$AD$170))+SUMPRODUCT(--($R$40:$R$170<>"")*($AH$40:$AH$170<>"")*($R$40:$R$170<>$AH$40:$AH$170))+SUMPRODUCT(--($R$40:$R$170<>"")*($AL$40:$AL$170<>"")*($R$40:$R$170<>$AL$40:$AL$170))+SUMPRODUCT(--($R$40:$R$170<>"")*($AP$40:$AP$170<>"")*($R$40:$R$170<>$AP$40:$AP$170))+SUMPRODUCT(--($R$40:$R$170<>"")*($AT$40:$AT$170<>"")*($R$40:$R$170<>$AT$40:$AT$170))+SUMPRODUCT(--($R$40:$R$170<>"")*($AX$40:$AX$170<>"")*($R$40:$R$170<>$AX$40:$AX$170))+SUMPRODUCT(--($R$40:$R$170<>"")*($BB$40:$BB$170<>"")*($R$40:$R$170<>$BB$40:$BB$170))+SUMPRODUCT(--($R$40:$R$170<>"")*($BF$40:$BF$170<>"")*($R$40:$R$170<>$BF$40:$BF$170))+SUMPRODUCT(--($R$40:$R$170<>"")*($BJ$40:$BJ$170<>"")*($R$40:$R$170<>$BJ$40:$BJ$170)),"") | D34: =IF(C34="","",IF(C34=0,"OK — blocks are row-aligned","MISALIGNED: "&C34&" rows differ. Do not use these numbers; switch the value columns to INDEX/MATCH on the date."))
R36: Staging — one BQL call per security. Each spills DATE and value; the working columns on the left look them up by date. Blocks: R = JGB 2s10s long · V = JGB 2s10s short · Z = JGB 10s30s long · AD = JGB 10s30s short · AH = UST 2s10s long · AL = UST 2s10s short · AP = UST 5s30s long · AT = UST 5s30s short · AX = Bund 2s10s long · BB = Bund 2s10s short · BF = KTB 3s10s long · BJ = KTB 3s10s short. If a block comes back with an extra ID column, shift that block's value column by one — nothing else needs to change.
A38: Slope history, monthly — 5 years, bp | R38: =BQL("GTJPY10Y Govt","px_last(frq=M, dates=range("&TEXT(Start5Y,"yyyy-mm-dd")&","&TEXT(AsOf,"yyyy-mm-dd")&"), fill=prev)") | V38: =BQL("GTJPY2Y Govt","px_last(frq=M, dates=range("&TEXT(Start5Y,"yyyy-mm-dd")&","&TEXT(AsOf,"yyyy-mm-dd")&"), fill=prev)") | Z38: =BQL("GTJPY30Y Govt","px_last(frq=M, dates=range("&TEXT(Start5Y,"yyyy-mm-dd")&","&TEXT(AsOf,"yyyy-mm-dd")&"), fill=prev)") | AD38: =BQL("GTJPY10Y Govt","px_last(frq=M, dates=range("&TEXT(Start5Y,"yyyy-mm-dd")&","&TEXT(AsOf,"yyyy-mm-dd")&"), fill=prev)") | AH38: =BQL("USGG10YR Index","px_last(frq=M, dates=range("&TEXT(Start5Y,"yyyy-mm-dd")&","&TEXT(AsOf,"yyyy-mm-dd")&"), fill=prev)") | AL38: =BQL("USGG2YR Index","px_last(frq=M, dates=range("&TEXT(Start5Y,"yyyy-mm-dd")&","&TEXT(AsOf,"yyyy-mm-dd")&"), fill=prev)") | AP38: =BQL("USGG30YR Index","px_last(frq=M, dates=range("&TEXT(Start5Y,"yyyy-mm-dd")&","&TEXT(AsOf,"yyyy-mm-dd")&"), fill=prev)") | AT38: =BQL("USGG5YR Index","px_last(frq=M, dates=range("&TEXT(Start5Y,"yyyy-mm-dd")&","&TEXT(AsOf,"yyyy-mm-dd")&"), fill=prev)") | AX38: =BQL("GTDEM10Y Govt","px_last(frq=M, dates=range("&TEXT(Start5Y,"yyyy-mm-dd")&","&TEXT(AsOf,"yyyy-mm-dd")&"), fill=prev)") | BB38: =BQL("GTDEM2Y Govt","px_last(frq=M, dates=range("&TEXT(Start5Y,"yyyy-mm-dd")&","&TEXT(AsOf,"yyyy-mm-dd")&"), fill=prev)") | BF38: =BQL("GTKRW10Y Govt","px_last(frq=M, dates=range("&TEXT(Start5Y,"yyyy-mm-dd")&","&TEXT(AsOf,"yyyy-mm-dd")&"), fill=prev)") | BJ38: =BQL("GTKRW3Y Govt","px_last(frq=M, dates=range("&TEXT(Start5Y,"yyyy-mm-dd")&","&TEXT(AsOf,"yyyy-mm-dd")&"), fill=prev)")
A39: Date | B39: JGB 2s10s | C39: JGB 10s30s | D39: UST 2s10s | E39: UST 5s30s | F39: Bund 2s10s | G39: KTB 3s10s
A40: =IFERROR(INDEX($R$40:$R$170,ROW()-39),"") | B40: =IFERROR((INDEX($S$40:$S$170,ROW()-39)-INDEX($W$40:$W$170,ROW()-39))*100,"") | C40: =IFERROR((INDEX($AA$40:$AA$170,ROW()-39)-INDEX($AE$40:$AE$170,ROW()-39))*100,"") | D40: =IFERROR((INDEX($AI$40:$AI$170,ROW()-39)-INDEX($AM$40:$AM$170,ROW()-39))*100,"") | E40: =IFERROR((INDEX($AQ$40:$AQ$170,ROW()-39)-INDEX($AU$40:$AU$170,ROW()-39))*100,"") | F40: =IFERROR((INDEX($AY$40:$AY$170,ROW()-39)-INDEX($BC$40:$BC$170,ROW()-39))*100,"") | G40: =IFERROR((INDEX($BG$40:$BG$170,ROW()-39)-INDEX($BK$40:$BK$170,ROW()-39))*100,"")
A41: =IFERROR(INDEX($R$40:$R$170,ROW()-39),"") | B41: =IFERROR((INDEX($S$40:$S$170,ROW()-39)-INDEX($W$40:$W$170,ROW()-39))*100,"") | C41: =IFERROR((INDEX($AA$40:$AA$170,ROW()-39)-INDEX($AE$40:$AE$170,ROW()-39))*100,"") | D41: =IFERROR((INDEX($AI$40:$AI$170,ROW()-39)-INDEX($AM$40:$AM$170,ROW()-39))*100,"") | E41: =IFERROR((INDEX($AQ$40:$AQ$170,ROW()-39)-INDEX($AU$40:$AU$170,ROW()-39))*100,"") | F41: =IFERROR((INDEX($AY$40:$AY$170,ROW()-39)-INDEX($BC$40:$BC$170,ROW()-39))*100,"") | G41: =IFERROR((INDEX($BG$40:$BG$170,ROW()-39)-INDEX($BK$40:$BK$170,ROW()-39))*100,"")
A42: =IFERROR(INDEX($R$40:$R$170,ROW()-39),"") | B42: =IFERROR((INDEX($S$40:$S$170,ROW()-39)-INDEX($W$40:$W$170,ROW()-39))*100,"") | C42: =IFERROR((INDEX($AA$40:$AA$170,ROW()-39)-INDEX($AE$40:$AE$170,ROW()-39))*100,"") | D42: =IFERROR((INDEX($AI$40:$AI$170,ROW()-39)-INDEX($AM$40:$AM$170,ROW()-39))*100,"") | E42: =IFERROR((INDEX($AQ$40:$AQ$170,ROW()-39)-INDEX($AU$40:$AU$170,ROW()-39))*100,"") | F42: =IFERROR((INDEX($AY$40:$AY$170,ROW()-39)-INDEX($BC$40:$BC$170,ROW()-39))*100,"") | G42: =IFERROR((INDEX($BG$40:$BG$170,ROW()-39)-INDEX($BK$40:$BK$170,ROW()-39))*100,"")
A43: =IFERROR(INDEX($R$40:$R$170,ROW()-39),"") | B43: =IFERROR((INDEX($S$40:$S$170,ROW()-39)-INDEX($W$40:$W$170,ROW()-39))*100,"") | C43: =IFERROR((INDEX($AA$40:$AA$170,ROW()-39)-INDEX($AE$40:$AE$170,ROW()-39))*100,"") | D43: =IFERROR((INDEX($AI$40:$AI$170,ROW()-39)-INDEX($AM$40:$AM$170,ROW()-39))*100,"") | E43: =IFERROR((INDEX($AQ$40:$AQ$170,ROW()-39)-INDEX($AU$40:$AU$170,ROW()-39))*100,"") | F43: =IFERROR((INDEX($AY$40:$AY$170,ROW()-39)-INDEX($BC$40:$BC$170,ROW()-39))*100,"") | G43: =IFERROR((INDEX($BG$40:$BG$170,ROW()-39)-INDEX($BK$40:$BK$170,ROW()-39))*100,"")
A44: =IFERROR(INDEX($R$40:$R$170,ROW()-39),"") | B44: =IFERROR((INDEX($S$40:$S$170,ROW()-39)-INDEX($W$40:$W$170,ROW()-39))*100,"") | C44: =IFERROR((INDEX($AA$40:$AA$170,ROW()-39)-INDEX($AE$40:$AE$170,ROW()-39))*100,"") | D44: =IFERROR((INDEX($AI$40:$AI$170,ROW()-39)-INDEX($AM$40:$AM$170,ROW()-39))*100,"") | E44: =IFERROR((INDEX($AQ$40:$AQ$170,ROW()-39)-INDEX($AU$40:$AU$170,ROW()-39))*100,"") | F44: =IFERROR((INDEX($AY$40:$AY$170,ROW()-39)-INDEX($BC$40:$BC$170,ROW()-39))*100,"") | G44: =IFERROR((INDEX($BG$40:$BG$170,ROW()-39)-INDEX($BK$40:$BK$170,ROW()-39))*100,"")
A45: =IFERROR(INDEX($R$40:$R$170,ROW()-39),"") | B45: =IFERROR((INDEX($S$40:$S$170,ROW()-39)-INDEX($W$40:$W$170,ROW()-39))*100,"") | C45: =IFERROR((INDEX($AA$40:$AA$170,ROW()-39)-INDEX($AE$40:$AE$170,ROW()-39))*100,"") | D45: =IFERROR((INDEX($AI$40:$AI$170,ROW()-39)-INDEX($AM$40:$AM$170,ROW()-39))*100,"") | E45: =IFERROR((INDEX($AQ$40:$AQ$170,ROW()-39)-INDEX($AU$40:$AU$170,ROW()-39))*100,"") | F45: =IFERROR((INDEX($AY$40:$AY$170,ROW()-39)-INDEX($BC$40:$BC$170,ROW()-39))*100,"") | G45: =IFERROR((INDEX($BG$40:$BG$170,ROW()-39)-INDEX($BK$40:$BK$170,ROW()-39))*100,"")
A46: =IFERROR(INDEX($R$40:$R$170,ROW()-39),"") | B46: =IFERROR((INDEX($S$40:$S$170,ROW()-39)-INDEX($W$40:$W$170,ROW()-39))*100,"") | C46: =IFERROR((INDEX($AA$40:$AA$170,ROW()-39)-INDEX($AE$40:$AE$170,ROW()-39))*100,"") | D46: =IFERROR((INDEX($AI$40:$AI$170,ROW()-39)-INDEX($AM$40:$AM$170,ROW()-39))*100,"") | E46: =IFERROR((INDEX($AQ$40:$AQ$170,ROW()-39)-INDEX($AU$40:$AU$170,ROW()-39))*100,"") | F46: =IFERROR((INDEX($AY$40:$AY$170,ROW()-39)-INDEX($BC$40:$BC$170,ROW()-39))*100,"") | G46: =IFERROR((INDEX($BG$40:$BG$170,ROW()-39)-INDEX($BK$40:$BK$170,ROW()-39))*100,"")
A47: =IFERROR(INDEX($R$40:$R$170,ROW()-39),"") | B47: =IFERROR((INDEX($S$40:$S$170,ROW()-39)-INDEX($W$40:$W$170,ROW()-39))*100,"") | C47: =IFERROR((INDEX($AA$40:$AA$170,ROW()-39)-INDEX($AE$40:$AE$170,ROW()-39))*100,"") | D47: =IFERROR((INDEX($AI$40:$AI$170,ROW()-39)-INDEX($AM$40:$AM$170,ROW()-39))*100,"") | E47: =IFERROR((INDEX($AQ$40:$AQ$170,ROW()-39)-INDEX($AU$40:$AU$170,ROW()-39))*100,"") | F47: =IFERROR((INDEX($AY$40:$AY$170,ROW()-39)-INDEX($BC$40:$BC$170,ROW()-39))*100,"") | G47: =IFERROR((INDEX($BG$40:$BG$170,ROW()-39)-INDEX($BK$40:$BK$170,ROW()-39))*100,"")
A48: =IFERROR(INDEX($R$40:$R$170,ROW()-39),"") | B48: =IFERROR((INDEX($S$40:$S$170,ROW()-39)-INDEX($W$40:$W$170,ROW()-39))*100,"") | C48: =IFERROR((INDEX($AA$40:$AA$170,ROW()-39)-INDEX($AE$40:$AE$170,ROW()-39))*100,"") | D48: =IFERROR((INDEX($AI$40:$AI$170,ROW()-39)-INDEX($AM$40:$AM$170,ROW()-39))*100,"") | E48: =IFERROR((INDEX($AQ$40:$AQ$170,ROW()-39)-INDEX($AU$40:$AU$170,ROW()-39))*100,"") | F48: =IFERROR((INDEX($AY$40:$AY$170,ROW()-39)-INDEX($BC$40:$BC$170,ROW()-39))*100,"") | G48: =IFERROR((INDEX($BG$40:$BG$170,ROW()-39)-INDEX($BK$40:$BK$170,ROW()-39))*100,"")
A49: =IFERROR(INDEX($R$40:$R$170,ROW()-39),"") | B49: =IFERROR((INDEX($S$40:$S$170,ROW()-39)-INDEX($W$40:$W$170,ROW()-39))*100,"") | C49: =IFERROR((INDEX($AA$40:$AA$170,ROW()-39)-INDEX($AE$40:$AE$170,ROW()-39))*100,"") | D49: =IFERROR((INDEX($AI$40:$AI$170,ROW()-39)-INDEX($AM$40:$AM$170,ROW()-39))*100,"") | E49: =IFERROR((INDEX($AQ$40:$AQ$170,ROW()-39)-INDEX($AU$40:$AU$170,ROW()-39))*100,"") | F49: =IFERROR((INDEX($AY$40:$AY$170,ROW()-39)-INDEX($BC$40:$BC$170,ROW()-39))*100,"") | G49: =IFERROR((INDEX($BG$40:$BG$170,ROW()-39)-INDEX($BK$40:$BK$170,ROW()-39))*100,"")
A50: =IFERROR(INDEX($R$40:$R$170,ROW()-39),"") | B50: =IFERROR((INDEX($S$40:$S$170,ROW()-39)-INDEX($W$40:$W$170,ROW()-39))*100,"") | C50: =IFERROR((INDEX($AA$40:$AA$170,ROW()-39)-INDEX($AE$40:$AE$170,ROW()-39))*100,"") | D50: =IFERROR((INDEX($AI$40:$AI$170,ROW()-39)-INDEX($AM$40:$AM$170,ROW()-39))*100,"") | E50: =IFERROR((INDEX($AQ$40:$AQ$170,ROW()-39)-INDEX($AU$40:$AU$170,ROW()-39))*100,"") | F50: =IFERROR((INDEX($AY$40:$AY$170,ROW()-39)-INDEX($BC$40:$BC$170,ROW()-39))*100,"") | G50: =IFERROR((INDEX($BG$40:$BG$170,ROW()-39)-INDEX($BK$40:$BK$170,ROW()-39))*100,"")
A51: =IFERROR(INDEX($R$40:$R$170,ROW()-39),"") | B51: =IFERROR((INDEX($S$40:$S$170,ROW()-39)-INDEX($W$40:$W$170,ROW()-39))*100,"") | C51: =IFERROR((INDEX($AA$40:$AA$170,ROW()-39)-INDEX($AE$40:$AE$170,ROW()-39))*100,"") | D51: =IFERROR((INDEX($AI$40:$AI$170,ROW()-39)-INDEX($AM$40:$AM$170,ROW()-39))*100,"") | E51: =IFERROR((INDEX($AQ$40:$AQ$170,ROW()-39)-INDEX($AU$40:$AU$170,ROW()-39))*100,"") | F51: =IFERROR((INDEX($AY$40:$AY$170,ROW()-39)-INDEX($BC$40:$BC$170,ROW()-39))*100,"") | G51: =IFERROR((INDEX($BG$40:$BG$170,ROW()-39)-INDEX($BK$40:$BK$170,ROW()-39))*100,"")
... A169: =IFERROR(INDEX($R$40:$R$170,ROW()-39),"") | B169: =IFERROR((INDEX($S$40:$S$170,ROW()-39)-INDEX($W$40:$W$170,ROW()-39))*100,"") | C169: =IFERROR((INDEX($AA$40:$AA$170,ROW()-39)-INDEX($AE$40:$AE$170,ROW()-39))*100,"") | D169: =IFERROR((INDEX($AI$40:$AI$170,ROW()-39)-INDEX($AM$40:$AM$170,ROW()-39))*100,"") | E169: =IFERROR((INDEX($AQ$40:$AQ$170,ROW()-39)-INDEX($AU$40:$AU$170,ROW()-39))*100,"") | F169: =IFERROR((INDEX($AY$40:$AY$170,ROW()-39)-INDEX($BC$40:$BC$170,ROW()-39))*100,"") | G169: =IFERROR((INDEX($BG$40:$BG$170,ROW()-39)-INDEX($BK$40:$BK$170,ROW()-39))*100,"")

Sheet BullSteepener
A1: JPY bull steepener — 2s10s
A2: Receive 2y JPY OIS, pay 10y, DV01-neutral. Entry, exit and holding period come out of the mean-reversion tests below rather than out of a view.
A5: Why this trade — the four lines that carry it
A6: The objection | B6: 2s10s is at its steepest since 2010. That is the first question and it deserves the first answer.
A7: The answer | B7: Every basis point of that steepening came from the long end selling off. The 2-year has never rallied in this cycle. In 2010 it sat near the policy rate with nothing to give back; today it prices about two more hikes. That inventory is the trade.
A8: What this is NOT | B8: It is not a forecast that the BoJ pauses. Guidance points the other way: at the July press conference Ueda said CPI is likely to accelerate clearly above 2% from the second half of FY26, flagged a risk that underlying CPI deviates upward, and said the Bank could speed up the pace if conditions stay accommodative. Q2 GDP was revised up. Two Board members want to go faster. Anyone claiming the data supports a pause has stopped reading in April.
A9: What it is instead | B9: An asymmetry trade. The market prices about two hikes, the Bank guides hawkish, and positioning is hawkish. Everything is aligned on one outcome, which makes the alternative cheap. The alternative is the terms-of-trade channel the Bank's own April Outlook names — Japan is the developed world's largest net energy importer, an energy shock is a tax on real income rather than demand-led inflation, and core-core was 1.7% in June with household spending down seven months running. We are not forecasting that break. We are buying it while nothing is priced for it.
A10: Why it belongs in this book | B10: The book is long Japan banks on a rate-mechanical NIM story. This pays exactly when that fails. Two positions, negatively correlated through the same variable — the BoJ path.
A11: Live indications — where the trade stands right now
A12: Measure | B12: Ticker | C12: Value | D12: What it tells you
A13: BoJ policy rate, % | B13: BOJDTR Index | C13: =BDP($B13,"PX_LAST") | D13: 1.00% since June. Held 8-1 in July.
A14: JPY OIS 1y, % | B14: JYSO1 Curncy | C14: =BDP($B14,"PX_LAST") | D14: Roll point for the front leg.
A15: JPY OIS 2y, % | B15: JYSO2 Curncy | C15: =BDP($B15,"PX_LAST") | D15: The leg we receive.
A16: JPY OIS 5y, % | B16: JYSO5 Curncy | C16: =BDP($B16,"PX_LAST") | D16: Interpolation point for the roll.
A17: JPY OIS 10y, % | B17: JYSO10 Curncy | C17: =BDP($B17,"PX_LAST") | D17: The leg we pay.
A18: 2s10s, bp | C18: =IFERROR((C17-C15)*100,"") | D18: The spread. Everything below is about this.
A19: 2y less policy rate, bp | C19: =IFERROR((C15-C13)*100,"") | D19: The inventory. This is what can be handed back.
A20: Hikes priced to 1y, count | C20: =IFERROR((C14-C13)/0.25,"") | D20: Below about one, most of the trade has already happened.
A21: 2s10s percentile, 5y | C21: =IFERROR(PERCENTRANK.INC($D$108:$D$387,C18),"") | D21: Above 0.90 the level objection has teeth. Lead with the decomposition.
A22: Current z-score | C22: =IFERROR((C18-$C$24)/$C$25,"") | D22: Standard deviations from the 5-year mean. The entry metric.
A24: Is 2s10s mean-reverting? The tests, and what would fail them | C24: =IFERROR(AVERAGE($D$108:$D$387),"")
C25: =IFERROR(STDEV.S($D$108:$D$387),"")
A26: Test | B26: Statistic | C26: Value | D26: Threshold | E26: Verdict
A27: 5-year mean, bp | B27: AVERAGE | C27: =C24
A28: 5-year standard deviation, bp | B28: STDEV.S | C28: =C25
A29: AR(1) mean-reversion speed | B29: SLOPE(dY, Y-1) = lambda | C29: =IFERROR(SLOPE($E$108:$E$387,$F$108:$F$387),"") | D29: < 0 | E29: =IF(C29="","",IF(C29<0,"Negative — the series pulls back toward its mean","Positive — no mean reversion. Do not size off these tests."))
A30: Implied long-run mean, bp | B30: -intercept / lambda | C30: =IFERROR(-INTERCEPT($E$108:$E$387,$F$108:$F$387)/C29,"") | E30: Where the AR(1) says the series is pulled to. Compare with the simple mean above.
A31: Half-life of a deviation, weeks | B31: -LN(2) / LN(1+lambda) | C31: =IFERROR(IF(C29<0,-LN(2)/LN(1+C29),""),"") | E31: =IF(C31="","",IF(C31<40,"Inside a 3-6 month horizon — the trade has time to work","Longer than the horizon. Either widen the horizon or accept this is a carry trade."))
A32: Standard error of lambda | B32: STEYX / SQRT(DEVSQ) | C32: =IFERROR(STEYX($E$108:$E$387,$F$108:$F$387)/SQRT(DEVSQ($F$108:$F$387)),"")
A33: Dickey-Fuller t-statistic | B33: lambda / SE(lambda) | C33: =IFERROR(C29/C32,"") | D33: < -2.86 | E33: =IF(C33="","",IF(C33<-3.43,"Rejects a unit root at 1% — strong mean reversion",IF(C33<-2.86,"Rejects at 5% — mean reverting",IF(C33<-2.57,"Rejects at 10% only — weak","Cannot reject a unit root. The level tells you nothing about the next move."))))
A34: Variance ratio, 4 weeks | B34: Var(4w) / (4 x Var(1w)) | C34: =IFERROR(VAR.S($I$108:$I$387)/(4*VAR.S($E$108:$E$387)),"") | D34: < 1 | E34: Below 1 is mean reversion; above 1 is trending; 1 is a random walk.
A35: Variance ratio, 13 weeks | B35: Var(13w) / (13 x Var(1w)) | C35: =IFERROR(VAR.S($J$108:$J$387)/(13*VAR.S($E$108:$E$387)),"") | D35: < 1 | E35: =IF(C35="","",IF(C35<1,"Mean reverting over a quarter — consistent with the entry rule","Trending over a quarter. Momentum entry, not a value entry."))
A36: VR(13) z-statistic | B36: (VR-1) / SQRT(2(2q-1)(q-1)/(3qT)) | C36: =IFERROR((C35-1)/SQRT(2*(2*13-1)*(13-1)/(3*13*COUNT($E$108:$E$387))),"") | D36: < -1.96 | E36: Below -1.96 the variance ratio is significantly under 1 at 5%.
A37: Autocorrelation of weekly changes, lag 1 | B37: CORREL(dY_t, dY_t-1) | C37: =IFERROR(CORREL(OFFSET($E$108:$E$387,1,0),OFFSET($E$108:$E$387,0,0)),"") | E37: Negative supports reversion at weekly frequency; near zero is normal for a spread.
A38: Observations | B38: COUNT | C38: =COUNT($E$108:$E$387) | D38: > 150 | E38: Below about 150 weekly points the tests above are not worth quoting.
A40: The Dickey-Fuller critical values (-2.57 / -2.86 / -3.43 at 10 / 5 / 1%) and the variance-ratio z threshold are statistical constants, not market data — they are the only hardcoded numbers on this tab. Everything else recomputes on refresh.
A42: Read the tests in this order: if the Dickey-Fuller statistic does not reject a unit root, stop. The entry and exit levels below are derived from mean reversion, and without it they are decoration. Say that in the room before anyone else does.
A45: Entry and exit — derived from the tests, not chosen
A46: Rule | B46: Level, bp | C46: Basis | D46: Note
A47: Entry — value | B47: =IFERROR($C$24-$C$25,"") | C47: mean less 1 SD | D47: Where the curve is flat against its own history. The z-score entry.
...

Sheet JPYEvidence
A1: JPY bull steepener — the macro evidence, charted
A2: Two charts. The first is why the priced hikes rest on the wrong measure; the second is why rising wages have not become inflation.
A5: What each chart is for
A6: Chart 1 — CPI | B6: Headline against core-core, with the 2% target. Headline is crude oil and the BoJ's own April Outlook says it wanes; core-core is the measure the Bank targets in practice, and it was 1.7% in June, the lowest since August 2022. The hikes priced into the 2-year rest on the line that is going away.
A7: Chart 2 — wages vs spending | B7: Real wages rose 1.6% in June, a sixth straight month, with base pay up 3.4% and accelerating. That is the strongest argument against the trade and it belongs on the page. The answer is the second series: household spending has fallen seven months running. Income is rising and it is not being spent, and core-core still fell. The wage channel is working on paper and not in prices.
A10: Series and their tickers
A11: Series | B11: Ticker | C11: Latest | D11: Status
A12: Japan headline CPI y/y | B12: JNCPIYOY Index | C12: =BDP($B12,"PX_LAST") | D12: Confirmed pattern, unconfirmed identifier — SECF <GO>
A13: Japan core-core CPI y/y | B13: JCPNEFEY Index | C13: =BDP($B13,"PX_LAST") | D13: Confirmed pattern, unconfirmed identifier — SECF <GO>
A14: Japan real wages y/y | B14: JNLSRWY Index | C14: =BDP($B14,"PX_LAST") | D14: Candidate only. If it does not resolve, the labour series are on ECST S <GO> under Japan / earnings and Japan / household survey. | R14: Staging — one BQL call per security. Each spills DATE and value; the working columns on the left look them up by date. Blocks: R = Japan headline CPI y/y · V = Japan core-core CPI y/y · Z = Japan real wages y/y · AD = Japan household spending y/y. If a block comes back with an extra ID column, shift that block's value column by one — nothing else needs to change.
A15: Japan household spending y/y | B15: JNHSSPYY Index | C15: =BDP($B15,"PX_LAST") | D15: Candidate only. If it does not resolve, the labour series are on ECST S <GO> under Japan / earnings and Japan / household survey.
R16: =BQL("JNCPIYOY Index","px_last(frq=M, dates=range("&TEXT(Start5Y,"yyyy-mm-dd")&","&TEXT(AsOf,"yyyy-mm-dd")&"), fill=prev)") | V16: =BQL("JCPNEFEY Index","px_last(frq=M, dates=range("&TEXT(Start5Y,"yyyy-mm-dd")&","&TEXT(AsOf,"yyyy-mm-dd")&"), fill=prev)") | Z16: =BQL("JNLSRWY Index","px_last(frq=M, dates=range("&TEXT(Start5Y,"yyyy-mm-dd")&","&TEXT(AsOf,"yyyy-mm-dd")&"), fill=prev)") | AD16: =BQL("JNHSSPYY Index","px_last(frq=M, dates=range("&TEXT(Start5Y,"yyyy-mm-dd")&","&TEXT(AsOf,"yyyy-mm-dd")&"), fill=prev)")
A18: Date alignment check | C18: =IFERROR(SUMPRODUCT(--($R$20:$R$150<>"")*($V$20:$V$150<>"")*($R$20:$R$150<>$V$20:$V$150))+SUMPRODUCT(--($R$20:$R$150<>"")*($Z$20:$Z$150<>"")*($R$20:$R$150<>$Z$20:$Z$150))+SUMPRODUCT(--($R$20:$R$150<>"")*($AD$20:$AD$150<>"")*($R$20:$R$150<>$AD$20:$AD$150)),"") | D18: =IF(C18="","",IF(C18=0,"OK — blocks are row-aligned","MISALIGNED: "&C18&" rows differ. Do not use these numbers; switch the value columns to INDEX/MATCH on the date."))
A19: Date | B19: Japan headline CPI y/y | C19: Japan core-core CPI y/y | D19: Japan real wages y/y | E19: Japan household spending y/y | F19: 2% target
A20: =IFERROR(INDEX($R$20:$R$150,ROW()-19),"") | B20: =IFERROR(INDEX($S$20:$S$150,ROW()-19),"") | C20: =IFERROR(INDEX($W$20:$W$150,ROW()-19),"") | D20: =IFERROR(INDEX($AA$20:$AA$150,ROW()-19),"") | E20: =IFERROR(INDEX($AE$20:$AE$150,ROW()-19),"") | F20: =IF(A20="","",2)
A21: =IFERROR(INDEX($R$20:$R$150,ROW()-19),"") | B21: =IFERROR(INDEX($S$20:$S$150,ROW()-19),"") | C21: =IFERROR(INDEX($W$20:$W$150,ROW()-19),"") | D21: =IFERROR(INDEX($AA$20:$AA$150,ROW()-19),"") | E21: =IFERROR(INDEX($AE$20:$AE$150,ROW()-19),"") | F21: =IF(A21="","",2)
A22: =IFERROR(INDEX($R$20:$R$150,ROW()-19),"") | B22: =IFERROR(INDEX($S$20:$S$150,ROW()-19),"") | C22: =IFERROR(INDEX($W$20:$W$150,ROW()-19),"") | D22: =IFERROR(INDEX($AA$20:$AA$150,ROW()-19),"") | E22: =IFERROR(INDEX($AE$20:$AE$150,ROW()-19),"") | F22: =IF(A22="","",2)
A23: =IFERROR(INDEX($R$20:$R$150,ROW()-19),"") | B23: =IFERROR(INDEX($S$20:$S$150,ROW()-19),"") | C23: =IFERROR(INDEX($W$20:$W$150,ROW()-19),"") | D23: =IFERROR(INDEX($AA$20:$AA$150,ROW()-19),"") | E23: =IFERROR(INDEX($AE$20:$AE$150,ROW()-19),"") | F23: =IF(A23="","",2)
A24: =IFERROR(INDEX($R$20:$R$150,ROW()-19),"") | B24: =IFERROR(INDEX($S$20:$S$150,ROW()-19),"") | C24: =IFERROR(INDEX($W$20:$W$150,ROW()-19),"") | D24: =IFERROR(INDEX($AA$20:$AA$150,ROW()-19),"") | E24: =IFERROR(INDEX($AE$20:$AE$150,ROW()-19),"") | F24: =IF(A24="","",2)
A25: =IFERROR(INDEX($R$20:$R$150,ROW()-19),"") | B25: =IFERROR(INDEX($S$20:$S$150,ROW()-19),"") | C25: =IFERROR(INDEX($W$20:$W$150,ROW()-19),"") | D25: =IFERROR(INDEX($AA$20:$AA$150,ROW()-19),"") | E25: =IFERROR(INDEX($AE$20:$AE$150,ROW()-19),"") | F25: =IF(A25="","",2)
A26: =IFERROR(INDEX($R$20:$R$150,ROW()-19),"") | B26: =IFERROR(INDEX($S$20:$S$150,ROW()-19),"") | C26: =IFERROR(INDEX($W$20:$W$150,ROW()-19),"") | D26: =IFERROR(INDEX($AA$20:$AA$150,ROW()-19),"") | E26: =IFERROR(INDEX($AE$20:$AE$150,ROW()-19),"") | F26: =IF(A26="","",2)
A27: =IFERROR(INDEX($R$20:$R$150,ROW()-19),"") | B27: =IFERROR(INDEX($S$20:$S$150,ROW()-19),"") | C27: =IFERROR(INDEX($W$20:$W$150,ROW()-19),"") | D27: =IFERROR(INDEX($AA$20:$AA$150,ROW()-19),"") | E27: =IFERROR(INDEX($AE$20:$AE$150,ROW()-19),"") | F27: =IF(A27="","",2)
A28: =IFERROR(INDEX($R$20:$R$150,ROW()-19),"") | B28: =IFERROR(INDEX($S$20:$S$150,ROW()-19),"") | C28: =IFERROR(INDEX($W$20:$W$150,ROW()-19),"") | D28: =IFERROR(INDEX($AA$20:$AA$150,ROW()-19),"") | E28: =IFERROR(INDEX($AE$20:$AE$150,ROW()-19),"") | F28: =IF(A28="","",2)
A29: =IFERROR(INDEX($R$20:$R$150,ROW()-19),"") | B29: =IFERROR(INDEX($S$20:$S$150,ROW()-19),"") | C29: =IFERROR(INDEX($W$20:$W$150,ROW()-19),"") | D29: =IFERROR(INDEX($AA$20:$AA$150,ROW()-19),"") | E29: =IFERROR(INDEX($AE$20:$AE$150,ROW()-19),"") | F29: =IF(A29="","",2)
A30: =IFERROR(INDEX($R$20:$R$150,ROW()-19),"") | B30: =IFERROR(INDEX($S$20:$S$150,ROW()-19),"") | C30: =IFERROR(INDEX($W$20:$W$150,ROW()-19),"") | D30: =IFERROR(INDEX($AA$20:$AA$150,ROW()-19),"") | E30: =IFERROR(INDEX($AE$20:$AE$150,ROW()-19),"") | F30: =IF(A30="","",2)
A31: =IFERROR(INDEX($R$20:$R$150,ROW()-19),"") | B31: =IFERROR(INDEX($S$20:$S$150,ROW()-19),"") | C31: =IFERROR(INDEX($W$20:$W$150,ROW()-19),"") | D31: =IFERROR(INDEX($AA$20:$AA$150,ROW()-19),"") | E31: =IFERROR(INDEX($AE$20:$AE$150,ROW()-19),"") | F31: =IF(A31="","",2)
... A149: =IFERROR(INDEX($R$20:$R$150,ROW()-19),"") | B149: =IFERROR(INDEX($S$20:$S$150,ROW()-19),"") | C149: =IFERROR(INDEX($W$20:$W$150,ROW()-19),"") | D149: =IFERROR(INDEX($AA$20:$AA$150,ROW()-19),"") | E149: =IFERROR(INDEX($AE$20:$AE$150,ROW()-19),"") | F149: =IF(A149="","",2)
A152: Both charts are native Excel objects wired to the columns above, so copy either one straight onto a slide and it keeps its link to the refreshed data. The 2% target is a computed column rather than a drawn line, so it survives the copy.

Sheet Payoff
A1: Payoff, sizing, and the dates that settle it
A2: Scenario payoffs for both expressions, an expected value, and a falsification calendar with the number that ends the trade.
A5: Inputs — shaded cells are yours to set on the terminal
A6: Entry level, 2s10s bp | B6: =IFERROR(BullSteepener!C18,"") | H6: Defaults to spot. Overwrite with your fill.
A7: Target, bp | B7: =IFERROR(BullSteepener!B49,"") | H7: From the mean-reversion block on BullSteepener.
A8: Stop, bp | B8: =IFERROR(BullSteepener!B51,"") | H8: As above.
A9: Carry and roll, bp per quarter | B9: =IFERROR(BullSteepener!C84,"") | H9: Computed off the live curve.
A10: Horizon, quarters | B10: 2 | H10: Two quarters spans the Sep and Oct meetings and three core-core prints.
A11: Conditional premium, bp | B11: 18 | H11: 6m conditional bull steepener, receiver spread. JPY swaptions are quoted in NORMAL (Bachelier) vol in basis points, so price it off the vol surface and put the premium here in bp of notional. 18 is a placeholder until you do.
A12: Conditional strike, bp of steepening | B12: 15 | H12: How far the curve must steepen before the structure pays.
A13: Book size, $m | B13: 100 | H13: For the sizing block below.
A14: Rates sleeve, % of book | B14: 0.3 | H14: Trade 2 carries 30% in the macro deck. This shares that sleeve.
A17: What it makes, by state of the world
A18: Probabilities are the author's, over the BoJ path rather than over the macro scenarios in the main deck — they are a different partition and should not be confused with the 55 / 25 / 20. The 2y and 10y moves are the assumption; everything to the right of them is arithmetic.
A20: State | B20: Prob. | C20: 2y move, bp | D20: 10y move, bp | E20: 2s10s outcome | F20: Cash P&L, bp | G20: Conditional P&L, bp | H20: What it is
A21: BoJ pauses — bull steepening | B21: 0.3 | C21: -45 | D21: -3 | E21: =IFERROR($B$6+(D21-C21),"") | F21: =IFERROR((E21-$B$6)+$B$9*$B$10,"") | G21: =IFERROR(IF(C21<0,MAX(0,(E21-$B$6)-$B$12),0)-$B$11,"") | H21: The front end hands back the priced hikes. The state the trade is underwriting, and the only one where the conditional pays.
A22: Nothing happens — carry | B22: 0.35 | C22: -5 | D22: 2 | E22: =IFERROR($B$6+(D22-C22),"") | F22: =IFERROR((E22-$B$6)+$B$9*$B$10,"") | G22: =IFERROR(IF(C22<0,MAX(0,(E22-$B$6)-$B$12),0)-$B$11,"") | H22: The curve drifts. You collect carry and roll, and the conditional expires worthless.
A23: Supply-led bear steepening | B23: 0.15 | C23: 10 | D23: 37 | E23: =IFERROR($B$6+(D23-C23),"") | F23: =IFERROR((E23-$B$6)+$B$9*$B$10,"") | G23: =IFERROR(IF(C23<0,MAX(0,(E23-$B$6)-$B$12),0)-$B$11,"") | H23: The consensus JGB trade. The cash spread is along for the ride; the conditional is not, because the front end never rallies.
A24: BoJ delivers — bear flattening | B24: 0.15 | C24: 30 | D24: 7 | E24: =IFERROR($B$6+(D24-C24),"") | F24: =IFERROR((E24-$B$6)+$B$9*$B$10,"") | G24: =IFERROR(IF(C24<0,MAX(0,(E24-$B$6)-$B$12),0)-$B$11,"") | H24: Sep and Oct hikes land. The cash spread loses; the conditional loses premium only. This is the state the July minutes point to.
A25: Risk-off bull flattening | B25: 0.05 | C25: -10 | D25: -28 | E25: =IFERROR($B$6+(D25-C25),"") | F25: =IFERROR((E25-$B$6)+$B$9*$B$10,"") | G25: =IFERROR(IF(C25<0,MAX(0,(E25-$B$6)-$B$12),0)-$B$11,"") | H25: A global duration rally where the long end leads. The one state where both legs of the cash spread work against you.
A27: Expected value
A28: Probability check | B28: =SUM($B$21:$B$25) | H28: Must be 100%. If it is not, the numbers below mean nothing.
A29: Cash spread, expected bp | B29: =SUMPRODUCT($B$21:$B$25,$F$21:$F$25) | H29: Probability-weighted, including carry.
A30: Conditional, expected bp | B30: =SUMPRODUCT($B$21:$B$25,$G$21:$G$25) | H30: Probability-weighted, net of premium.
A31: Cash — probability of loss | B31: =SUMIF($F$21:$F$25,"<0",$B$21:$B$25) | H31: How often the cash spread is a losing trade.
A32: Conditional — probability of loss | B32: =SUMIF($G$21:$G$25,"<0",$B$21:$B$25) | H32: Higher hit rate of small losses, and that is the point — the losses are capped at premium.
A33: Cash — worst state, bp | B33: =MIN($F$21:$F$25) | H33: Compare with the stop. If the worst state is beyond the stop, the stop is what you actually own.
A34: Conditional — worst state, bp | B34: =MIN($G$21:$G$25) | H34: Premium, by construction.
A36: =IF(COUNT($F$21:$G$25)=0,"Set the inputs and this reads itself.","Expected value: "&TEXT(SUMPRODUCT($B$21:$B$25,$F$21:$F$25),"+0.0;-0.0")&"bp on the cash spread against "&TEXT(SUMPRODUCT($B$21:$B$25,$G$21:$G$25),"+0.0;-0.0")&"bp on the conditional — but the cash spread loses in "&TEXT(SUMIF($F$21:$F$25,"<0",$B$21:$B$25),"0%")&" of states against "&TEXT(SUMIF($G$21:$G$25,"<0",$B$21:$B$25),"0%")&" for the conditional, and its worst state is "&TEXT(MIN($F$21:$F$25),"0")&"bp against a capped "&TEXT(MIN($G$21:$G$25),"0")&"bp.")
A39: Sizing
A40: Rates sleeve, $m | B40: =IFERROR($B$13*$B$14,"") | H40: The sleeve this trade shares with the US 5s30s.
A41: Distance to stop, bp | B41: =IFERROR($B$6-$B$8,"") | H41: Entry less stop.
A42: Cash — max loss at stop, $m | B42: =IFERROR($B$40*ABS($B$41)/10000*10,"") | H42: At a DV01 sized so a 10bp adverse move costs 0.1% of the sleeve. Replace the factor with your desk's DV01 convention.
A43: Cash — max loss, % of book | B43: =IFERROR($B$42/$B$13,"") | H43: The number the PM actually asks for.
A44: Conditional — max loss, $m | B44: =IFERROR($B$40*$B$11/10000*10,"") | H44: Premium only, and it is known on day one.
A45: Conditional — max loss, % of book | B45: =IFERROR($B$44/$B$13,"") | H45: Pre-sized, no stop required, survives a gap.
A48: The falsification calendar — dated, with the number
A49: The July minutes show several Board members expecting inflation to accelerate significantly in the second half of the fiscal year, and two favouring faster hikes on firms' willingness to raise prices. That is the strongest argument against this trade and it is testable on a known date. Our reading is that broad-based price increases are cost pass-through from the same crude shock the April Outlook says will wane — so core-core is the arbiter, not headline.
A51: Date | B51: Event | C51: What kills the trade | H51: What confirms it
A52: 18 Sep 2026 | B52: BoJ policy meeting | C52: A hike delivered WITH hawkish guidance on the path | H52: A hike delivered as a one-and-done — that is the entry, not the exit
...

Sheet MacroLink
A1: Tying the trade to the macro framing
A2: The steepener is Channel 2 expressed in rates. These are the artefacts that show it rather than assert it.
A5: Every channel, and the instrument that expresses it
A6: Channel | B6: The number | C6: Instrument | D6: Direction | F6: Why this instrument
A7: 1 · Fed / discount rate | B7: UST 10y 3.97 → 4.71% | C7: US 5s30s steepener | D7: Bear steepener | F7: Term premium widens whether the Fed hikes or loses credibility. Trade 2, already in the book.
A8: 2 · Energy / terms of trade | B8: Brent $72 → $102 → $88 | C8: JPY 2s10s bull steepener | D8: Bull steepener | F8: Japan is the G7's largest net energy importer. The BoJ's own Outlook writes the terms-of-trade hit into its forecasts. This trade.
A9: 3 · Tariffs | B9: 10–12.5%, statutory | C9: Japan vs Korea equity spread | D9: Relative value | F9: A permanent margin tax, concentrated in Korean and Taiwanese electronics and near zero for Japanese domestic demand. Trade 1.
A10: 4 · Capital cycle | B10: China DUV, ~$270bn | C10: Short Korea semis | D10: Directional | F10: A terminal-value event, not an earnings event. Trade 1's short leg.
A12: The point of this table is that no trade is orphaned. If a position cannot be traced to a channel it should not be in the book, and if a channel has no instrument the framing is decorative.
A14: What each position does in each state
A15: Position | B15: BASE 55% | C15: BEAR 25% | D15: BULL 20% | E15: BoJ delivers | F15: Read
A16: JPY 2s10s bull steepener | B16: Carry | C16: Pays | D16: Loses | E16: Loses | F16: Pays in the state that kills the equity book.
A17: Trade 1 · long Japan banks | B17: Pays | C17: Loses | D17: Pays | E17: Pays | F17: The mirror image. Between them, all four states are covered.
A18: Trade 2 · US 5s30s | B18: Carry | C18: Pays | D18: Loses | E18: Neutral | F18: Same shape as the JPY leg, opposite engine.
A19: Trade 3 · gold call spread | B19: Premium | C19: Pays | D19: Loses | E19: Neutral | F19: Convexity against both tails.
A21: Scenario probabilities are the author's, carried over from the macro deck. The fourth column is new: it is the state where the BoJ simply delivers what is priced, and it is the only one where this trade and Trade 1 disagree. That disagreement is the reason to hold both.
A24: Is it crowded? — where the street actually is
A25: Trade | B25: Street positioning | C25: Us | F25: What it means
A26: JGB 10s30s | B26: Flatteners — consensus | C26: Not in it | F26: The long-end premium is technical, and the MoF is fixing the technical by cutting super-long issuance to a 17-year low. The street is right, and it is not our trade.
